[2023-08-27T01:40:51.296+0000] {taskinstance.py:1159} INFO - Dependencies all met for dep_context=non-requeueable deps ti=<TaskInstance: analytics_pipeline_dag.run_pipeline_task manual__2023-08-27T01:40:42.049661+00:00 [queued]>
[2023-08-27T01:40:51.300+0000] {taskinstance.py:1159} INFO - Dependencies all met for dep_context=requeueable deps ti=<TaskInstance: analytics_pipeline_dag.run_pipeline_task manual__2023-08-27T01:40:42.049661+00:00 [queued]>
[2023-08-27T01:40:51.300+0000] {taskinstance.py:1361} INFO - Starting attempt 1 of 2
[2023-08-27T01:40:51.308+0000] {taskinstance.py:1382} INFO - Executing <Task(PythonOperator): run_pipeline_task> on 2023-08-27 01:40:42.049661+00:00
[2023-08-27T01:40:51.318+0000] {standard_task_runner.py:57} INFO - Started process 116 to run task
[2023-08-27T01:40:51.320+0000] {standard_task_runner.py:84} INFO - Running: ['***', 'tasks', 'run', 'analytics_pipeline_dag', 'run_pipeline_task', 'manual__2023-08-27T01:40:42.049661+00:00', '--job-id', '45', '--raw', '--subdir', 'DAGS_FOLDER/my_proyects/my_first_dag.py', '--cfg-path', '/tmp/tmp8_35d7l6']
[2023-08-27T01:40:51.321+0000] {standard_task_runner.py:85} INFO - Job 45: Subtask run_pipeline_task
[2023-08-27T01:40:51.346+0000] {task_command.py:415} INFO - Running <TaskInstance: analytics_pipeline_dag.run_pipeline_task manual__2023-08-27T01:40:42.049661+00:00 [running]> on host 63d26ffcb055
[2023-08-27T01:40:51.391+0000] {taskinstance.py:1660} INFO - Exporting env vars: AIRFLOW_CTX_DAG_OWNER='***' AIRFLOW_CTX_DAG_ID='analytics_pipeline_dag' AIRFLOW_CTX_TASK_ID='run_pipeline_task' AIRFLOW_CTX_EXECUTION_DATE='2023-08-27T01:40:42.049661+00:00' AIRFLOW_CTX_TRY_NUMBER='1' AIRFLOW_CTX_DAG_RUN_ID='manual__2023-08-27T01:40:42.049661+00:00'
[2023-08-27T01:40:52.289+0000] {taskinstance.py:1943} ERROR - Task failed with exception
Traceback (most recent call last):
  File "/home/airflow/.local/lib/python3.8/site-packages/airflow/operators/python.py", line 192, in execute
    return_value = self.execute_callable()
  File "/home/airflow/.local/lib/python3.8/site-packages/airflow/operators/python.py", line 209, in execute_callable
    return self.python_callable(*self.op_args, **self.op_kwargs)
  File "/opt/airflow/dags/my_proyects/my_first_dag.py", line 50, in run_analytics_pipeline
    data_df['week_start_date'] = week_start_date_strings
NameError: name 'week_start_date_strings' is not defined
[2023-08-27T01:40:52.297+0000] {taskinstance.py:1400} INFO - Marking task as UP_FOR_RETRY. dag_id=analytics_pipeline_dag, task_id=run_pipeline_task, execution_date=20230827T014042, start_date=20230827T014051, end_date=20230827T014052
[2023-08-27T01:40:52.309+0000] {standard_task_runner.py:104} ERROR - Failed to execute job 45 for task run_pipeline_task (name 'week_start_date_strings' is not defined; 116)
[2023-08-27T01:40:52.334+0000] {local_task_job_runner.py:228} INFO - Task exited with return code 1
[2023-08-27T01:40:52.350+0000] {taskinstance.py:2784} INFO - 0 downstream tasks scheduled from follow-on schedule check
